Workbook

Sheet CPI Data
A1: cpi_date | B1: actual_cpi | C1: forecast_cpi | D1: surprise | E1: nq_0829 | F1: nq_0835 | G1: nq_0845 | H1: nq_close | I1: move_pts_5m | J1: move_pct_5m | K1: move_pts_15m | L1: move_pct_15m | M1: move_pts_close | N1: move_pct_close | O1: initial_direction | P1: close_direction | Q1: direction_match | R1: abs_surprise | S1: abs_5m_move
A2: 46122 | B2: 3.3 | C2: 3.4 | D2: =B2-C2 -> -0.1 | E2: 25336.25 | F2: 25303 | G2: 25312.5 | H2: 25284.25 | I2: =F2-E2 -> -33.25 | J2: =(F2-E2)/E2 -> -0.0013123489 | K2: =G2-E2 -> -23.75 | L2: =(G2-E2)/E2 -> -0.00093739208 | M2: =H2-E2 -> -52 | N2: =(H2-E2)/E2 -> -0.0020523953 | O2: {=_xlfn.IFS(I2>0,"UP",I2<0,"DOWN",I2=0,"FLAT")} -> DOWN | P2: {=_xlfn.IFS(M2>0,"UP",M2<0,"DOWN",M2=0,"FLAT")} -> DOWN | Q2: {=_xlfn.IFS(O2=P2,"MATCH",O2<>P2,"NO")} -> MATCH | R2: =--ABS(D2) -> 0.1 | S2: =ABS(J2) -> 0.0013123489
A3: 46092 | B3: 2.4 | C3: 2.4 | D3: =B3-C3 -> 0 | E3: 25215.5 | F3: 25166.75 | G3: 25137.5 | H3: 25188.5 | I3: =F3-E3 -> -48.75 | J3: =(F3-E3)/E3 -> -0.0019333347 | K3: =G3-E3 -> -78 | L3: =(G3-E3)/E3 -> -0.0030933354 | M3: =H3-E3 -> -27 | N3: =(H3-E3)/E3 -> -0.00107077 | O3: {=_xlfn.IFS(I3>0,"UP",I3<0,"DOWN",I3=0,"FLAT")} -> DOWN | P3: {=_xlfn.IFS(M3>0,"UP",M3<0,"DOWN",M3=0,"FLAT")} -> DOWN | Q3: {=_xlfn.IFS(O3=P3,"MATCH",O3<>P3,"NO")} -> MATCH | R3: =--ABS(D3) -> 0 | S3: =ABS(J3) -> 0.0019333347
A4: 46066 | B4: 2.4 | C4: 2.5 | D4: =B4-C4 -> -0.1 | E4: 24921.75 | F4: 24980.25 | G4: 24975 | H4: 25032.5 | I4: =F4-E4 -> 58.5 | J4: =(F4-E4)/E4 -> 0.0023473472 | K4: =G4-E4 -> 53.25 | L4: =(G4-E4)/E4 -> 0.0021366878 | M4: =H4-E4 -> 110.75 | N4: =(H4-E4)/E4 -> 0.0044439094 | O4: {=_xlfn.IFS(I4>0,"UP",I4<0,"DOWN",I4=0,"FLAT")} -> UP | P4: {=_xlfn.IFS(M4>0,"UP",M4<0,"DOWN",M4=0,"FLAT")} -> UP | Q4: {=_xlfn.IFS(O4=P4,"MATCH",O4<>P4,"NO")} -> MATCH | R4: =--ABS(D4) -> 0.1 | S4: =ABS(J4) -> 0.0023473472
A5: 46035 | B5: 2.7 | C5: 2.7 | D5: =B5-C5 -> 0 | E5: 26127.25 | F5: 26240.5 | G5: 26201.5 | H5: 26136.75 | I5: =F5-E5 -> 113.25 | J5: =(F5-E5)/E5 -> 0.0043345549 | K5: =G5-E5 -> 74.25 | L5: =(G5-E5)/E5 -> 0.0028418605 | M5: =H5-E5 -> 9.5 | N5: =(H5-E5)/E5 -> 0.00036360505 | O5: {=_xlfn.IFS(I5>0,"UP",I5<0,"DOWN",I5=0,"FLAT")} -> UP | P5: {=_xlfn.IFS(M5>0,"UP",M5<0,"DOWN",M5=0,"FLAT")} -> UP | Q5: {=_xlfn.IFS(O5=P5,"MATCH",O5<>P5,"NO")} -> MATCH | R5: =--ABS(D5) -> 0 | S5: =ABS(J5) -> 0.0043345549
A6: 46009 | B6: 2.7 | C6: 3.1 | D6: =B6-C6 -> -0.4 | E6: 25329.75 | F6: 25377.25 | G6: 25458 | H6: 25461.5 | I6: =F6-E6 -> 47.5 | J6: =(F6-E6)/E6 -> 0.0018752653 | K6: =G6-E6 -> 128.25 | L6: =(G6-E6)/E6 -> 0.0050632162 | M6: =H6-E6 -> 131.75 | N6: =(H6-E6)/E6 -> 0.0052013936 | O6: {=_xlfn.IFS(I6>0,"UP",I6<0,"DOWN",I6=0,"FLAT")} -> UP | P6: {=_xlfn.IFS(M6>0,"UP",M6<0,"DOWN",M6=0,"FLAT")} -> UP | Q6: {=_xlfn.IFS(O6=P6,"MATCH",O6<>P6,"NO")} -> MATCH | R6: =--ABS(D6) -> 0.4 | S6: =ABS(J6) -> 0.0018752653
A7: 45954 | B7: 3 | C7: 3.1 | D7: =B7-C7 -> -0.1 | E7: 25832.25 | F7: 25951 | G7: 25946.25 | H7: 25973 | I7: =F7-E7 -> 118.75 | J7: =(F7-E7)/E7 -> 0.004596967 | K7: =G7-E7 -> 114 | L7: =(G7-E7)/E7 -> 0.0044130883 | M7: =H7-E7 -> 140.75 | N7: =(H7-E7)/E7 -> 0.0054486156 | O7: {=_xlfn.IFS(I7>0,"UP",I7<0,"DOWN",I7=0,"FLAT")} -> UP | P7: {=_xlfn.IFS(M7>0,"UP",M7<0,"DOWN",M7=0,"FLAT")} -> UP | Q7: {=_xlfn.IFS(O7=P7,"MATCH",O7<>P7,"NO")} -> MATCH | R7: =--ABS(D7) -> 0.1 | S7: =ABS(J7) -> 0.004596967
A8: 45911 | B8: 2.9 | C8: 2.9 | D8: =B8-C8 -> 0 | E8: 24654.5 | F8: 24615.5 | G8: 24633.25 | H8: 24712.75 | I8: =F8-E8 -> -39 | J8: =(F8-E8)/E8 -> -0.0015818613 | K8: =G8-E8 -> -21.25 | L8: =(G8-E8)/E8 -> -0.00086191162 | M8: =H8-E8 -> 58.25 | N8: =(H8-E8)/E8 -> 0.0023626518 | O8: {=_xlfn.IFS(I8>0,"UP",I8<0,"DOWN",I8=0,"FLAT")} -> DOWN | P8: {=_xlfn.IFS(M8>0,"UP",M8<0,"DOWN",M8=0,"FLAT")} -> UP | Q8: {=_xlfn.IFS(O8=P8,"MATCH",O8<>P8,"NO")} -> NO | R8: =--ABS(D8) -> 0 | S8: =ABS(J8) -> 0.0015818613
A9: 45881 | B9: 2.7 | C9: 2.8 | D9: =B9-C9 -> -0.1 | E9: 24375.25 | F9: 24488.5 | G9: 24489.25 | H9: 24640.5 | I9: =F9-E9 -> 113.25 | J9: =(F9-E9)/E9 -> 0.0046461062 | K9: =G9-E9 -> 114 | L9: =(G9-E9)/E9 -> 0.0046768751 | M9: =H9-E9 -> 265.25 | N9: =(H9-E9)/E9 -> 0.01088194 | O9: {=_xlfn.IFS(I9>0,"UP",I9<0,"DOWN",I9=0,"FLAT")} -> UP | P9: {=_xlfn.IFS(M9>0,"UP",M9<0,"DOWN",M9=0,"FLAT")} -> UP | Q9: {=_xlfn.IFS(O9=P9,"MATCH",O9<>P9,"NO")} -> MATCH | R9: =--ABS(D9) -> 0.1 | S9: =ABS(J9) -> 0.0046461062
A10: 45853 | B10: 2.7 | C10: 2.6 | D10: =B10-C10 -> 0.1 | E10: 23857.5 | F10: 23894 | G10: 23874.75 | H10: 23758.5 | I10: =F10-E10 -> 36.5 | J10: =(F10-E10)/E10 -> 0.0015299172 | K10: =G10-E10 -> 17.25 | L10: =(G10-E10)/E10 -> 0.00072304307 | M10: =H10-E10 -> -99 | N10: =(H10-E10)/E10 -> -0.0041496385 | O10: {=_xlfn.IFS(I10>0,"UP",I10<0,"DOWN",I10=0,"FLAT")} -> UP | P10: {=_xlfn.IFS(M10>0,"UP",M10<0,"DOWN",M10=0,"FLAT")} -> DOWN | Q10: {=_xlfn.IFS(O10=P10,"MATCH",O10<>P10,"NO")} -> NO | R10: =--ABS(D10) -> 0.1 | S10: =ABS(J10) -> 0.0015299172
A11: 45819 | B11: 2.4 | C11: 2.5 | D11: =B11-C11 -> -0.1 | E11: 22879.5 | F11: 22988.5 | G11: 22973.75 | H11: 22795.25 | I11: =F11-E11 -> 109 | J11: =(F11-E11)/E11 -> 0.0047640901 | K11: =G11-E11 -> 94.25 | L11: =(G11-E11)/E11 -> 0.0041194082 | M11: =H11-E11 -> -84.25 | N11: =(H11-E11)/E11 -> -0.0036823357 | O11: {=_xlfn.IFS(I11>0,"UP",I11<0,"DOWN",I11=0,"FLAT")} -> UP | P11: {=_xlfn.IFS(M11>0,"UP",M11<0,"DOWN",M11=0,"FLAT")} -> DOWN | Q11: {=_xlfn.IFS(O11=P11,"MATCH",O11<>P11,"NO")} -> NO | R11: =--ABS(D11) -> 0.1 | S11: =ABS(J11) -> 0.0047640901
A12: 45790 | B12: 2.3 | C12: 2.4 | D12: =B12-C12 -> -0.1 | E12: 21910.75 | F12: 21947 | G12: 21908.25 | H12: 22173.5 | I12: =F12-E12 -> 36.25 | J12: =(F12-E12)/E12 -> 0.001654439 | K12: =G12-E12 -> -2.5 | L12: =(G12-E12)/E12 -> -0.00011409924 | M12: =H12-E12 -> 262.75 | N12: =(H12-E12)/E12 -> 0.01199183 | O12: {=_xlfn.IFS(I12>0,"UP",I12<0,"DOWN",I12=0,"FLAT")} -> UP | P12: {=_xlfn.IFS(M12>0,"UP",M12<0,"DOWN",M12=0,"FLAT")} -> UP | Q12: {=_xlfn.IFS(O12=P12,"MATCH",O12<>P12,"NO")} -> MATCH | R12: =--ABS(D12) -> 0.1 | S12: =ABS(J12) -> 0.001654439
A13: 45757 | B13: 2.4 | C13: 2.5 | D13: =B13-C13 -> -0.1 | E13: 19764 | F13: 19838.75 | G13: 19719.5 | H13: 19406 | I13: =F13-E13 -> 74.75 | J13: =(F13-E13)/E13 -> 0.0037821291 | K13: =G13-E13 -> -44.5 | L13: =(G13-E13)/E13 -> -0.0022515685 | M13: =H13-E13 -> -358 | N13: =(H13-E13)/E13 -> -0.018113742 | O13: {=_xlfn.IFS(I13>0,"UP",I13<0,"DOWN",I13=0,"FLAT")} -> UP | P13: {=_xlfn.IFS(M13>0,"UP",M13<0,"DOWN",M13=0,"FLAT")} -> DOWN | Q13: {=_xlfn.IFS(O13=P13,"MATCH",O13<>P13,"NO")} -> NO | R13: =--ABS(D13) -> 0.1 | S13: =ABS(J13) -> 0.0037821291
... A52: 44573 | B52: 7 | C52: 7 | D52: =B52-C52 -> 0 | E52: 19000 | F52: 19010.25 | G52: 19077 | H52: 19011.25 | I52: =F52-E52 -> 10.25 | J52: =(F52-E52)/E52 -> 0.00053947368 | K52: =G52-E52 -> 77 | L52: =(G52-E52)/E52 -> 0.0040526316 | M52: =H52-E52 -> 11.25 | N52: =(H52-E52)/E52 -> 0.00059210526 | O52: {=_xlfn.IFS(I52>0,"UP",I52<0,"DOWN",I52=0,"FLAT")} -> UP | P52: {=_xlfn.IFS(M52>0,"UP",M52<0,"DOWN",M52=0,"FLAT")} -> UP | Q52: {=_xlfn.IFS(O52=P52,"MATCH",O52<>P52,"NO")} -> MATCH | R52: =--ABS(D52) -> 0 | S52: =ABS(J52) -> 0.00053947368

Sheet ANALYSIS
A1: Initial Direction Match Rate
A2: Match Count | B2: =COUNTIF('CPI Data'!Q2:Q52, "Match") -> 36
A3: Match Percentage | B3: =B2/COUNTA('CPI Data'!Q2:Q52) -> 0.70588235 | C3: On about 71% of CPI days, the initial 5-minute reaction correctly predicted the end-of-day direction on NASDAQ-100 Index futures
A5: Hotter CPI Count | B5: =COUNTIF('CPI Data'!D2:D52,">0") -> 17
A6: Hotter CPI + Red Close | B6: =COUNTIFS('CPI Data'!D2:D52,">0",'CPI Data'!P2:P52,"Down") -> 13 | C6: When CPI came in hotter than expected, NQ closed down about 76% of the time.
A7: Hotter CPI Red Close % | B7: =B6/B5 -> 0.76470588
A9: Cooler CPI Count | B9: =COUNTIF('CPI Data'!D2:D52,"<0") -> 21
A10: Cooler CPI + Green Close | B10: =COUNTIFS('CPI Data'!D2:D52,"<0",'CPI Data'!P2:P52,"UP") -> 14 | C10: When CPI came in cooler than expected, NQ closed green about 67% of the time.
A11: Cooler CPI Green Close % | B11: =B10/B9 -> 0.66666667
A13: Inline CPI Count | B13: =COUNTIF('CPI Data'!D2:D52,0) -> 13
A14: Inline CPI + Green Close | B14: =COUNTIFS('CPI Data'!D2:D52,0,'CPI Data'!P2:P52,"UP") -> 12 | C14: When CPI matched expectations exactly, NQ still closed green most of the time.
A15: Inline CPI Green Close % | B15: =B14/B13 -> 0.92307692 | C15: small sample SIZE
A16: Inline CPI + Red Close | B16: =COUNTIFS('CPI Data'!D2:D52,0,'CPI Data'!P2:P52,"DOWN") -> 1
A17: Inline CPI Red Close % | B17: =B16/B13 -> 0.076923077
A19: Initial UP + Close DOWN | B19: =COUNTIFS('CPI Data'!O2:O52,"UP",'CPI Data'!P2:P52,"DOWN") -> 8
A20: Initial DOWN + Close UP | B20: =COUNTIFS('CPI Data'!O2:O52,"DOWN",'CPI Data'!P2:P52,"UP") -> 7 | C20: About 29% of CPI days reversed direction after the initial reaction.
A21: Total Reversals | B21: =B19+B20 -> 15
A22: Reversal Percentage | B22: =B21/COUNTA('CPI Data'!Q2:Q52) -> 0.29411765
A24: Initial UP Count | B24: =COUNTIF('CPI Data'!O2:O52,"UP") -> 31
A25: Initial UP + Close UP | B25: =COUNTIFS('CPI Data'!O2:O52,"UP",'CPI Data'!P2:P52,"UP") -> 23
A26: Initial UP Follow-Through % | B26: =B25/B24 -> 0.74193548
C27: Bullish initial reactions had strong continuation.
A28: Initial DOWN Count | B28: =COUNTIF('CPI Data'!O2:O52,"DOWN") -> 20
A29: Initial DOWN + Close DOWN | B29: =COUNTIFS('CPI Data'!O2:O52,"DOWN",'CPI Data'!P2:P52,"DOWN") -> 13
A30: Initial DOWN Follow-Through % | B30: =B29/B28 -> 0.65
A33: Avg 5m Move % - Hotter CPI | B33: =AVERAGEIF('CPI Data'!D2:D52,">0",'CPI Data'!J2:J52) -> -0.0081662518
A34: Avg 5m Move % - Cooler CPI | B34: =AVERAGEIF('CPI Data'!D2:D52,"<0",'CPI Data'!J2:J52) -> 0.0049861607
A35: Avg 5m Move % - Inline CPI | B35: =AVERAGEIF('CPI Data'!D2:D52,0,'CPI Data'!J2:J52) -> 0.0020256801
A36: Avg Close Move % - Hotter CPI | B36: =AVERAGEIF('CPI Data'!D2:D52,">0",'CPI Data'!N2:N52) -> -0.0091044322 | C36: Bearish reaction persisted/slightly worsened
A37: Avg Close Move % - Cooler CPI | B37: =AVERAGEIF('CPI Data'!D2:D52,"<0",'CPI Data'!N2:N52) -> 0.0043945777 | C37: Bullish reaction faded slightly
A38: Avg Close Move % - Inline CPI | B38: =AVERAGEIF('CPI Data'!D2:D52,0,'CPI Data'!N2:N52) -> 0.0074086579 | C38: Muted initial reaction but strong bullish drift later
A41: Biggest Bullish Close Move | B41: =MAX('CPI Data'!N:N) -> 0.054005871
A42: Biggest Bearish Close Move | B42: =MIN('CPI Data'!N:N) -> -0.050434018
A43: Biggest 5m Bullish Reaction | B43: =MAX('CPI Data'!J:J) -> 0.022473933 | C43: CPI releases were capable of producing major directional and volatility shocks in the market.
A44: Biggest 5m Bearish Reaction | B44: =MIN('CPI Data'!J:J) -> -0.028217777
A45: Biggest 15m Bullish Reaction | B45: =MAX('CPI Data'!L:L) -> 0.02744413
A46: Biggest 15m Bearish Reaction | B46: =MIN('CPI Data'!L:L) -> -0.028720065
A47: Biggest Reversal Day | B47: {=MAX(ABS('CPI Data'!M2:M52-'CPI Data'!I2:I52))} -> 542
A49: Correlation: Surprise Size vs 5m Move Size | B49: =CORREL('CPI Data'!R2:R52,'CPI Data'!S2:S52) -> 0.43922828 | C49: Larger CPI surprises tended to create larger immediate 5-minute moves in NQ futures.
A50: Correlation: Surprise Size vs Close Move Size | B50: {=CORREL('CPI Data'!R2:R52,ABS('CPI Data'!N2:N52))} -> 0.32063513 | C50: The relationship weakened by the close
...

Sheet Charts
A1: CPI Type | B1: Avg Close Move % | L1: Abs CPI Surprise | M1: Abs 5m Move % | AA1: Outcome Type | AB1: Percentage | AP1: 5m Move % | AQ1: 15m Move %
A2: Hotter CPI | B2: -0.0091 | L2: ='CPI Data'!R2 -> 0.1 | M2: ='CPI Data'!S2 -> 0.0013123489 | AA2: Follow-Through | AB2: 0.7059 | AP2: ='CPI Data'!J2 -> -0.0013123489 | AQ2: ='CPI Data'!L2 -> -0.00093739208
A3: Cooler CPI | B3: 0.0044 | L3: ='CPI Data'!R3 -> 0 | M3: ='CPI Data'!S3 -> 0.0019333347 | AA3: Reversal | AB3: 0.2941 | AP3: ='CPI Data'!J3 -> -0.0019333347 | AQ3: ='CPI Data'!L3 -> -0.0030933354
A4: Inline CPI | B4: 0.0074 | L4: ='CPI Data'!R4 -> 0.1 | M4: ='CPI Data'!S4 -> 0.0023473472 | AP4: ='CPI Data'!J4 -> 0.0023473472 | AQ4: ='CPI Data'!L4 -> 0.0021366878
L5: ='CPI Data'!R5 -> 0 | M5: ='CPI Data'!S5 -> 0.0043345549 | AP5: ='CPI Data'!J5 -> 0.0043345549 | AQ5: ='CPI Data'!L5 -> 0.0028418605
L6: ='CPI Data'!R6 -> 0.4 | M6: ='CPI Data'!S6 -> 0.0018752653 | AP6: ='CPI Data'!J6 -> 0.0018752653 | AQ6: ='CPI Data'!L6 -> 0.0050632162
L7: ='CPI Data'!R7 -> 0.1 | M7: ='CPI Data'!S7 -> 0.004596967 | AP7: ='CPI Data'!J7 -> 0.004596967 | AQ7: ='CPI Data'!L7 -> 0.0044130883
L8: ='CPI Data'!R8 -> 0 | M8: ='CPI Data'!S8 -> 0.0015818613 | AP8: ='CPI Data'!J8 -> -0.0015818613 | AQ8: ='CPI Data'!L8 -> -0.00086191162
L9: ='CPI Data'!R9 -> 0.1 | M9: ='CPI Data'!S9 -> 0.0046461062 | AP9: ='CPI Data'!J9 -> 0.0046461062 | AQ9: ='CPI Data'!L9 -> 0.0046768751
L10: ='CPI Data'!R10 -> 0.1 | M10: ='CPI Data'!S10 -> 0.0015299172 | AP10: ='CPI Data'!J10 -> 0.0015299172 | AQ10: ='CPI Data'!L10 -> 0.00072304307
L11: ='CPI Data'!R11 -> 0.1 | M11: ='CPI Data'!S11 -> 0.0047640901 | AP11: ='CPI Data'!J11 -> 0.0047640901 | AQ11: ='CPI Data'!L11 -> 0.0041194082
L12: ='CPI Data'!R12 -> 0.1 | M12: ='CPI Data'!S12 -> 0.001654439 | AP12: ='CPI Data'!J12 -> 0.001654439 | AQ12: ='CPI Data'!L12 -> -0.00011409924
L13: ='CPI Data'!R13 -> 0.1 | M13: ='CPI Data'!S13 -> 0.0037821291 | AP13: ='CPI Data'!J13 -> 0.0037821291 | AQ13: ='CPI Data'!L13 -> -0.0022515685
L14: ='CPI Data'!R14 -> 0.1 | M14: ='CPI Data'!S14 -> 0.004970023 | AP14: ='CPI Data'!J14 -> 0.004970023 | AQ14: ='CPI Data'!L14 -> 0.0029916644
L15: ='CPI Data'!R15 -> 0.1 | M15: ='CPI Data'!S15 -> 0.010226419 | AP15: ='CPI Data'!J15 -> -0.010226419 | AQ15: ='CPI Data'!L15 -> -0.011990721
L16: ='CPI Data'!R16 -> 0 | M16: ='CPI Data'!S16 -> 0.013153434 | AP16: ='CPI Data'!J16 -> 0.013153434 | AQ16: ='CPI Data'!L16 -> 0.013345538
... L25: ='CPI Data'!R25 -> 0.1 | M25: ='CPI Data'!S25 -> 0.01366426 | AP25: ='CPI Data'!J25 -> -0.01366426 | AQ25: ='CPI Data'!L25 -> -0.016259363
L26: ='CPI Data'!R26 -> 0.1 | M26: ='CPI Data'!S26 -> 0.0014719343 | O26: Larger CPI surprises generally corresponded with larger immediate NQ reactions, | AP26: ='CPI Data'!J26 -> 0.0014719343 | AQ26: ='CPI Data'!L26 -> 0.0032530985
L27: ='CPI Data'!R27 -> 0.2 | M27: ='CPI Data'!S27 -> 0.0076349232 | O27: though the relationship remained moderate due to broader market noise and variability in macro sentiment. | AP27: ='CPI Data'!J27 -> -0.0076349232 | AQ27: ='CPI Data'!L27 -> -0.0080972672
L28: ='CPI Data'!R28 -> 0.2 | M28: ='CPI Data'!S28 -> 0.004012402 | AP28: ='CPI Data'!J28 -> -0.004012402 | AQ28: ='CPI Data'!L28 -> -0.0047028478
L29: ='CPI Data'!R29 -> 0 | M29: ='CPI Data'!S29 -> 0.0021807771 | AP29: ='CPI Data'!J29 -> -0.0021807771 | AQ29: ='CPI Data'!L29 -> -0.011653109
L30: ='CPI Data'!R30 -> 0.1 | M30: ='CPI Data'!S30 -> 0.010712149 | AP30: ='CPI Data'!J30 -> 0.010712149 | AQ30: ='CPI Data'!L30 -> 0.011115594
L31: ='CPI Data'!R31 -> 0.1 | M31: ='CPI Data'!S31 -> 0.00301602 | AP31: ='CPI Data'!J31 -> -0.00301602 | AQ31: ='CPI Data'!L31 -> -0.002889768
L32: ='CPI Data'!R32 -> 0.1 | M32: ='CPI Data'!S32 -> 0.0017070816 | AP32: ='CPI Data'!J32 -> -0.0017070816 | AQ32: ='CPI Data'!L32 -> -0.0014272321
L33: ='CPI Data'!R33 -> 0.1 | M33: ='CPI Data'!S33 -> 0.00034985096 | AP33: ='CPI Data'!J33 -> 0.00034985096 | AQ33: ='CPI Data'!L33 -> -0.0010215648
L34: ='CPI Data'!R34 -> 0.1 | M34: ='CPI Data'!S34 -> 0.0054643281 | AP34: ='CPI Data'!J34 -> 0.0054643281 | AQ34: ='CPI Data'!L34 -> 0.0048773671
L35: ='CPI Data'!R35 -> 0.1 | M35: ='CPI Data'!S35 -> 0.00062437031 | AP35: ='CPI Data'!J35 -> 0.00062437031 | AQ35: ='CPI Data'!L35 -> 0.0033063246
L36: ='CPI Data'!R36 -> 0.1 | M36: ='CPI Data'!S36 -> 0.0034170164 | AP36: ='CPI Data'!J36 -> 0.0034170164 | AQ36: ='CPI Data'!L36 -> 0.0072865145
L37: ='CPI Data'!R37 -> 0.1 | M37: ='CPI Data'!S37 -> 0.01119173 | AP37: ='CPI Data'!J37 -> 0.01119173 | AQ37: ='CPI Data'!L37 -> 0.0091051359
L38: ='CPI Data'!R38 -> 0 | M38: ='CPI Data'!S38 -> 0.0015087255 | AP38: ='CPI Data'!J38 -> -0.0015087255 | AQ38: ='CPI Data'!L38 -> 0.00031850871
L39: ='CPI Data'!R39 -> 0.2 | M39: ='CPI Data'!S39 -> 0.0023115594 | AP39: ='CPI Data'!J39 -> 0.0023115594 | AQ39: ='CPI Data'!L39 -> -0.0036209043
... L52: ='CPI Data'!R52 -> 0 | M52: ='CPI Data'!S52 -> 0.00053947368 | AP52: ='CPI Data'!J52 -> 0.00053947368 | AQ52: ='CPI Data'!L52 -> 0.0040526316
